ERROR:ex:Error!
Traceback (most recent call last):
  File "D:/code/foodbot5000/foodbot5000.py", line 40, in run_bot
    self.load_json()
  File "D:/code/foodbot5000/foodbot5000.py", line 29, in load_json
    with open('./data/data.json') as json_file:
FileNotFoundError: [Errno 2] No such file or directory: './data/data.json'
ERROR:Logbot 5000: :JSON file not found.
Traceback (most recent call last):
  File "D:/code/foodbot5000/foodbot5000.py", line 40, in run_bot
    self.load_json()
  File "D:/code/foodbot5000/foodbot5000.py", line 29, in load_json
    with open('./data/data.json') as json_file:
FileNotFoundError: [Errno 2] No such file or directory: './data/data.json'
2017-10-05 13:15:31,354 - Logbot 5000 - ERROR - JSON file not found.
Traceback (most recent call last):
  File "D:/code/foodbot5000/foodbot5000.py", line 44, in run_bot
    self.load_json()
  File "D:/code/foodbot5000/foodbot5000.py", line 33, in load_json
    with open('./data/data.json') as json_file:
FileNotFoundError: [Errno 2] No such file or directory: './data/data.json'
2017-10-05 13:17:48,371 - Logbot 5000 - ERROR - JSON file not found.
Traceback (most recent call last):
  File "D:/code/foodbot5000/foodbot5000.py", line 44, in run_bot
    self.load_json()
  File "D:/code/foodbot5000/foodbot5000.py", line 33, in load_json
    with open('./data/data.json') as json_file:
FileNotFoundError: [Errno 2] No such file or directory: './data/data.json'
2017-10-05 13:19:27,137 - Logbot 5000 - INFO - Program started
2017-10-05 13:19:28,302 - Logbot 5000 - INFO - Program finished
2017-10-05 13:22:11,425 - Logbot 5000 - INFO - Program started
2017-10-05 13:22:52,932 - Logbot 5000 - INFO - Program started
2017-10-05 13:22:52,933 - Logbot 5000 - ERROR - JSON key not found in file
Traceback (most recent call last):
  File "D:/code/foodbot5000/foodbot5000.py", line 45, in run_bot
    self.load_json()
  File "D:/code/foodbot5000/foodbot5000.py", line 36, in load_json
    self.max_id = self.json_data['yolo']
KeyError: 'yolo'
2017-10-05 13:24:21,640 - Logbot 5000 - INFO - Program started
2017-10-05 13:24:21,640 - Logbot 5000 - ERROR - JSON key not found in file
Traceback (most recent call last):
  File "D:/code/foodbot5000/foodbot5000.py", line 45, in run_bot
    self.load_json()
  File "D:/code/foodbot5000/foodbot5000.py", line 36, in load_json
    self.max_id = self.json_data['max_id']
KeyError: 'max_id'
2017-10-05 13:24:55,329 - Logbot 5000 - INFO - Program started
2017-10-05 13:24:56,518 - Logbot 5000 - INFO - Program finished
